2018-01-04 23:06:26,169 [salt.utils.parsers                       ][WARNING ][17] Master received a SIGTERM. Exiting.
2018-01-04 23:16:23,359 [salt.utils.parsers                       ][WARNING ][517] Master received a SIGTERM. Exiting.
2018-01-04 23:17:06,459 [salt.utils.verify][WARNING ][960] Insecure logging configuration detected! Sensitive data may be logged.
2018-01-04 23:19:54,480 [salt.utils.parsers][WARNING ][960] Master received a SIGINT. Exiting.
2018-01-05 15:46:00,642 [salt.utils.parsers][WARNING ][3487] Master received a SIGTERM. Exiting.
2018-01-05 16:20:39,251 [salt.utils.parsers][WARNING ][916] Master received a SIGTERM. Exiting.
2018-01-05 16:32:41,631 [salt.utils.parsers][WARNING ][8901] Master received a SIGTERM. Exiting.
2018-01-05 17:34:07,173 [salt.utils.parsers][WARNING ][27916] Master received a SIGTERM. Exiting.
2018-01-05 17:39:41,378 [salt.utils.parsers][WARNING ][32174] Master received a SIGTERM. Exiting.
2018-01-05 17:56:53,219 [salt.utils.parsers][WARNING ][2252] Master received a SIGTERM. Exiting.
2018-01-05 17:56:57,724 [salt.auth        ][WARNING ][8750] Authentication failure of type "user" occurred.
2018-01-05 17:59:08,158 [salt.auth        ][WARNING ][8737] Authorization failure occurred.
2018-01-05 17:59:08,160 [salt.transport.zeromq][ERROR   ][8737] Some exception handling a payload from minion
Traceback (most recent call last):
  File "/usr/lib/python2.7/dist-packages/salt/transport/zeromq.py", line 620, in handle_message
    ret, req_opts = yield self.payload_handler(payload)
  File "/usr/lib/python2.7/dist-packages/tornado/gen.py", line 870, in run
    value = future.result()
  File "/usr/lib/python2.7/dist-packages/tornado/concurrent.py", line 215, in result
    raise_exc_info(self._exc_info)
  File "/usr/lib/python2.7/dist-packages/tornado/gen.py", line 215, in wrapper
    result = func(*args, **kwargs)
  File "/usr/lib/python2.7/dist-packages/salt/master.py", line 894, in _handle_payload
    'clear': self._handle_clear}[key](load)
  File "/usr/lib/python2.7/dist-packages/salt/master.py", line 908, in _handle_clear
    return getattr(self.clear_funcs, load['cmd'])(load), {'fun': 'send_clear'}
  File "/usr/lib/python2.7/dist-packages/salt/master.py", line 1710, in runner
    if not self.ckminions.runner_check(auth_list, clear_load['fun']):
  File "/usr/lib/python2.7/dist-packages/salt/utils/minions.py", line 1028, in runner_check
    for ind in auth_list:
TypeError: 'NoneType' object is not iterable
2018-01-05 17:59:08,165 [salt.auth        ][WARNING ][8734] Authorization failure occurred.
2018-01-05 17:59:08,166 [salt.transport.zeromq][ERROR   ][8734] Some exception handling a payload from minion
Traceback (most recent call last):
  File "/usr/lib/python2.7/dist-packages/salt/transport/zeromq.py", line 620, in handle_message
    ret, req_opts = yield self.payload_handler(payload)
  File "/usr/lib/python2.7/dist-packages/tornado/gen.py", line 870, in run
    value = future.result()
  File "/usr/lib/python2.7/dist-packages/tornado/concurrent.py", line 215, in result
    raise_exc_info(self._exc_info)
  File "/usr/lib/python2.7/dist-packages/tornado/gen.py", line 215, in wrapper
    result = func(*args, **kwargs)
  File "/usr/lib/python2.7/dist-packages/salt/master.py", line 894, in _handle_payload
    'clear': self._handle_clear}[key](load)
  File "/usr/lib/python2.7/dist-packages/salt/master.py", line 908, in _handle_clear
    return getattr(self.clear_funcs, load['cmd'])(load), {'fun': 'send_clear'}
  File "/usr/lib/python2.7/dist-packages/salt/master.py", line 1710, in runner
    if not self.ckminions.runner_check(auth_list, clear_load['fun']):
  File "/usr/lib/python2.7/dist-packages/salt/utils/minions.py", line 1028, in runner_check
    for ind in auth_list:
TypeError: 'NoneType' object is not iterable
2018-01-05 17:59:08,178 [salt.auth        ][WARNING ][8750] Authorization failure occurred.
2018-01-05 17:59:08,179 [salt.transport.zeromq][ERROR   ][8750] Some exception handling a payload from minion
Traceback (most recent call last):
  File "/usr/lib/python2.7/dist-packages/salt/transport/zeromq.py", line 620, in handle_message
    ret, req_opts = yield self.payload_handler(payload)
  File "/usr/lib/python2.7/dist-packages/tornado/gen.py", line 870, in run
    value = future.result()
  File "/usr/lib/python2.7/dist-packages/tornado/concurrent.py", line 215, in result
    raise_exc_info(self._exc_info)
  File "/usr/lib/python2.7/dist-packages/tornado/gen.py", line 215, in wrapper
    result = func(*args, **kwargs)
  File "/usr/lib/python2.7/dist-packages/salt/master.py", line 894, in _handle_payload
    'clear': self._handle_clear}[key](load)
  File "/usr/lib/python2.7/dist-packages/salt/master.py", line 908, in _handle_clear
    return getattr(self.clear_funcs, load['cmd'])(load), {'fun': 'send_clear'}
  File "/usr/lib/python2.7/dist-packages/salt/master.py", line 1710, in runner
    if not self.ckminions.runner_check(auth_list, clear_load['fun']):
  File "/usr/lib/python2.7/dist-packages/salt/utils/minions.py", line 1028, in runner_check
    for ind in auth_list:
TypeError: 'NoneType' object is not iterable
2018-01-05 17:59:08,190 [salt.auth        ][WARNING ][8727] Authorization failure occurred.
2018-01-05 17:59:08,190 [salt.master      ][WARNING ][8727] Authentication failure of type "token" occurred.
2018-01-05 17:59:08,191 [salt.auth        ][WARNING ][8747] Authorization failure occurred.
2018-01-05 17:59:08,192 [salt.transport.zeromq][ERROR   ][8747] Some exception handling a payload from minion
Traceback (most recent call last):
  File "/usr/lib/python2.7/dist-packages/salt/transport/zeromq.py", line 620, in handle_message
    ret, req_opts = yield self.payload_handler(payload)
  File "/usr/lib/python2.7/dist-packages/tornado/gen.py", line 870, in run
    value = future.result()
  File "/usr/lib/python2.7/dist-packages/tornado/concurrent.py", line 215, in result
    raise_exc_info(self._exc_info)
  File "/usr/lib/python2.7/dist-packages/tornado/gen.py", line 215, in wrapper
    result = func(*args, **kwargs)
  File "/usr/lib/python2.7/dist-packages/salt/master.py", line 894, in _handle_payload
    'clear': self._handle_clear}[key](load)
  File "/usr/lib/python2.7/dist-packages/salt/master.py", line 908, in _handle_clear
    return getattr(self.clear_funcs, load['cmd'])(load), {'fun': 'send_clear'}
  File "/usr/lib/python2.7/dist-packages/salt/master.py", line 1710, in runner
    if not self.ckminions.runner_check(auth_list, clear_load['fun']):
  File "/usr/lib/python2.7/dist-packages/salt/utils/minions.py", line 1028, in runner_check
    for ind in auth_list:
TypeError: 'NoneType' object is not iterable
2018-01-05 17:59:21,658 [salt.auth        ][WARNING ][8734] Authorization failure occurred.
2018-01-05 17:59:21,658 [salt.transport.zeromq][ERROR   ][8734] Some exception handling a payload from minion
Traceback (most recent call last):
  File "/usr/lib/python2.7/dist-packages/salt/transport/zeromq.py", line 620, in handle_message
    ret, req_opts = yield self.payload_handler(payload)
  File "/usr/lib/python2.7/dist-packages/tornado/gen.py", line 870, in run
    value = future.result()
  File "/usr/lib/python2.7/dist-packages/tornado/concurrent.py", line 215, in result
    raise_exc_info(self._exc_info)
  File "/usr/lib/python2.7/dist-packages/tornado/gen.py", line 215, in wrapper
    result = func(*args, **kwargs)
  File "/usr/lib/python2.7/dist-packages/salt/master.py", line 894, in _handle_payload
    'clear': self._handle_clear}[key](load)
  File "/usr/lib/python2.7/dist-packages/salt/master.py", line 908, in _handle_clear
    return getattr(self.clear_funcs, load['cmd'])(load), {'fun': 'send_clear'}
  File "/usr/lib/python2.7/dist-packages/salt/master.py", line 1710, in runner
    if not self.ckminions.runner_check(auth_list, clear_load['fun']):
  File "/usr/lib/python2.7/dist-packages/salt/utils/minions.py", line 1028, in runner_check
    for ind in auth_list:
TypeError: 'NoneType' object is not iterable
2018-01-05 17:59:21,663 [salt.auth        ][WARNING ][8750] Authorization failure occurred.
2018-01-05 17:59:21,663 [salt.transport.zeromq][ERROR   ][8750] Some exception handling a payload from minion
Traceback (most recent call last):
  File "/usr/lib/python2.7/dist-packages/salt/transport/zeromq.py", line 620, in handle_message
    ret, req_opts = yield self.payload_handler(payload)
  File "/usr/lib/python2.7/dist-packages/tornado/gen.py", line 870, in run
    value = future.result()
  File "/usr/lib/python2.7/dist-packages/tornado/concurrent.py", line 215, in result
    raise_exc_info(self._exc_info)
  File "/usr/lib/python2.7/dist-packages/tornado/gen.py", line 215, in wrapper
    result = func(*args, **kwargs)
  File "/usr/lib/python2.7/dist-packages/salt/master.py", line 894, in _handle_payload
    'clear': self._handle_clear}[key](load)
  File "/usr/lib/python2.7/dist-packages/salt/master.py", line 908, in _handle_clear
    return getattr(self.clear_funcs, load['cmd'])(load), {'fun': 'send_clear'}
  File "/usr/lib/python2.7/dist-packages/salt/master.py", line 1710, in runner
    if not self.ckminions.runner_check(auth_list, clear_load['fun']):
  File "/usr/lib/python2.7/dist-packages/salt/utils/minions.py", line 1028, in runner_check
    for ind in auth_list:
TypeError: 'NoneType' object is not iterable
2018-01-05 18:03:08,330 [salt.auth        ][WARNING ][8737] Authorization failure occurred.
2018-01-05 18:03:08,330 [salt.transport.zeromq][ERROR   ][8737] Some exception handling a payload from minion
Traceback (most recent call last):
  File "/usr/lib/python2.7/dist-packages/salt/transport/zeromq.py", line 620, in handle_message
    ret, req_opts = yield self.payload_handler(payload)
  File "/usr/lib/python2.7/dist-packages/tornado/gen.py", line 870, in run
    value = future.result()
  File "/usr/lib/python2.7/dist-packages/tornado/concurrent.py", line 215, in result
    raise_exc_info(self._exc_info)
  File "/usr/lib/python2.7/dist-packages/tornado/gen.py", line 215, in wrapper
    result = func(*args, **kwargs)
  File "/usr/lib/python2.7/dist-packages/salt/master.py", line 894, in _handle_payload
    'clear': self._handle_clear}[key](load)
  File "/usr/lib/python2.7/dist-packages/salt/master.py", line 908, in _handle_clear
    return getattr(self.clear_funcs, load['cmd'])(load), {'fun': 'send_clear'}
  File "/usr/lib/python2.7/dist-packages/salt/master.py", line 1710, in runner
    if not self.ckminions.runner_check(auth_list, clear_load['fun']):
  File "/usr/lib/python2.7/dist-packages/salt/utils/minions.py", line 1028, in runner_check
    for ind in auth_list:
TypeError: 'NoneType' object is not iterable
2018-01-05 18:03:08,334 [salt.auth        ][WARNING ][8734] Authorization failure occurred.
2018-01-05 18:03:08,334 [salt.transport.zeromq][ERROR   ][8734] Some exception handling a payload from minion
Traceback (most recent call last):
  File "/usr/lib/python2.7/dist-packages/salt/transport/zeromq.py", line 620, in handle_message
    ret, req_opts = yield self.payload_handler(payload)
  File "/usr/lib/python2.7/dist-packages/tornado/gen.py", line 870, in run
    value = future.result()
  File "/usr/lib/python2.7/dist-packages/tornado/concurrent.py", line 215, in result
    raise_exc_info(self._exc_info)
  File "/usr/lib/python2.7/dist-packages/tornado/gen.py", line 215, in wrapper
    result = func(*args, **kwargs)
  File "/usr/lib/python2.7/dist-packages/salt/master.py", line 894, in _handle_payload
    'clear': self._handle_clear}[key](load)
  File "/usr/lib/python2.7/dist-packages/salt/master.py", line 908, in _handle_clear
    return getattr(self.clear_funcs, load['cmd'])(load), {'fun': 'send_clear'}
  File "/usr/lib/python2.7/dist-packages/salt/master.py", line 1710, in runner
    if not self.ckminions.runner_check(auth_list, clear_load['fun']):
  File "/usr/lib/python2.7/dist-packages/salt/utils/minions.py", line 1028, in runner_check
    for ind in auth_list:
TypeError: 'NoneType' object is not iterable
2018-01-05 18:03:08,387 [salt.auth        ][WARNING ][8750] Authorization failure occurred.
2018-01-05 18:03:08,388 [salt.master      ][WARNING ][8750] Authentication failure of type "token" occurred.
2018-01-05 18:10:07,413 [salt.utils.parsers][WARNING ][8682] Master received a SIGTERM. Exiting.
2018-01-05 18:11:10,716 [salt.utils.parsers][WARNING ][14073] Master received a SIGTERM. Exiting.
2018-01-05 18:11:34,439 [salt.pillar      ][ERROR   ][15282] SLS 'common' does not render to a dictionary
2018-01-05 18:11:34,439 [salt.pillar      ][ERROR   ][15282] The rendered pillar sls file, 'common' state did not return the expected data format. This is a sign of a malformed pillar sls file. Returned errors: 'SLS 'common' does not render to a dictionary'
2018-01-05 18:11:34,439 [salt.pillar      ][CRITICAL][15282] Pillar render error: SLS 'common' does not render to a dictionary
2018-01-05 18:12:39,692 [salt.pillar      ][ERROR   ][15279] SLS 'common' does not render to a dictionary
2018-01-05 18:12:39,692 [salt.pillar      ][ERROR   ][15279] The rendered pillar sls file, 'common' state did not return the expected data format. This is a sign of a malformed pillar sls file. Returned errors: 'SLS 'common' does not render to a dictionary'
2018-01-05 18:12:39,692 [salt.pillar      ][CRITICAL][15279] Pillar render error: SLS 'common' does not render to a dictionary
2018-01-05 18:13:02,106 [salt.pillar      ][ERROR   ][15288] SLS 'common' does not render to a dictionary
2018-01-05 18:13:02,106 [salt.pillar      ][ERROR   ][15288] The rendered pillar sls file, 'common' state did not return the expected data format. This is a sign of a malformed pillar sls file. Returned errors: 'SLS 'common' does not render to a dictionary'
2018-01-05 18:13:02,106 [salt.pillar      ][CRITICAL][15288] Pillar render error: SLS 'common' does not render to a dictionary
2018-01-05 18:13:05,091 [salt.pillar      ][ERROR   ][15281] SLS 'common' does not render to a dictionary
2018-01-05 18:13:05,091 [salt.pillar      ][ERROR   ][15281] The rendered pillar sls file, 'common' state did not return the expected data format. This is a sign of a malformed pillar sls file. Returned errors: 'SLS 'common' does not render to a dictionary'
2018-01-05 18:13:05,091 [salt.pillar      ][CRITICAL][15281] Pillar render error: SLS 'common' does not render to a dictionary
2018-01-05 18:19:29,253 [salt.utils.verify][WARNING ][18101] Insecure logging configuration detected! Sensitive data may be logged.
2018-01-05 18:19:29,395 [salt.pillar      ][ERROR   ][15288] SLS 'common' does not render to a dictionary
2018-01-05 18:19:29,395 [salt.pillar      ][ERROR   ][15288] The rendered pillar sls file, 'common' state did not return the expected data format. This is a sign of a malformed pillar sls file. Returned errors: 'SLS 'common' does not render to a dictionary'
2018-01-05 18:19:29,395 [salt.pillar      ][CRITICAL][15288] Pillar render error: SLS 'common' does not render to a dictionary
2018-01-05 18:19:49,935 [salt.pillar      ][ERROR   ][15282] SLS 'common' does not render to a dictionary
2018-01-05 18:19:49,936 [salt.pillar      ][ERROR   ][15282] The rendered pillar sls file, 'common' state did not return the expected data format. This is a sign of a malformed pillar sls file. Returned errors: 'SLS 'common' does not render to a dictionary'
2018-01-05 18:19:49,936 [salt.pillar      ][CRITICAL][15282] Pillar render error: SLS 'common' does not render to a dictionary
2018-01-05 18:19:49,984 [salt.pillar      ][ERROR   ][15280] SLS 'common' does not render to a dictionary
2018-01-05 18:19:49,984 [salt.pillar      ][ERROR   ][15280] The rendered pillar sls file, 'common' state did not return the expected data format. This is a sign of a malformed pillar sls file. Returned errors: 'SLS 'common' does not render to a dictionary'
2018-01-05 18:19:49,985 [salt.pillar      ][CRITICAL][15280] Pillar render error: SLS 'common' does not render to a dictionary
2018-01-05 18:21:55,765 [salt.utils.verify][WARNING ][18715] Insecure logging configuration detected! Sensitive data may be logged.
2018-01-05 18:25:07,062 [salt.auth        ][WARNING ][15280] Authorization failure occurred.
2018-01-05 18:25:07,063 [salt.transport.zeromq][ERROR   ][15280] Some exception handling a payload from minion
Traceback (most recent call last):
  File "/usr/lib/python2.7/dist-packages/salt/transport/zeromq.py", line 620, in handle_message
    ret, req_opts = yield self.payload_handler(payload)
  File "/usr/lib/python2.7/dist-packages/tornado/gen.py", line 870, in run
    value = future.result()
  File "/usr/lib/python2.7/dist-packages/tornado/concurrent.py", line 215, in result
    raise_exc_info(self._exc_info)
  File "/usr/lib/python2.7/dist-packages/tornado/gen.py", line 215, in wrapper
    result = func(*args, **kwargs)
  File "/usr/lib/python2.7/dist-packages/salt/master.py", line 894, in _handle_payload
    'clear': self._handle_clear}[key](load)
  File "/usr/lib/python2.7/dist-packages/salt/master.py", line 908, in _handle_clear
    return getattr(self.clear_funcs, load['cmd'])(load), {'fun': 'send_clear'}
  File "/usr/lib/python2.7/dist-packages/salt/master.py", line 1710, in runner
    if not self.ckminions.runner_check(auth_list, clear_load['fun']):
  File "/usr/lib/python2.7/dist-packages/salt/utils/minions.py", line 1028, in runner_check
    for ind in auth_list:
TypeError: 'NoneType' object is not iterable
2018-01-05 18:25:20,742 [salt.auth        ][WARNING ][15279] Authentication failure of type "eauth" occurred.
2018-01-05 18:25:20,743 [salt.master      ][WARNING ][15279] Authentication failure of type "eauth" occurred.
2018-01-05 18:31:51,620 [salt.auth        ][WARNING ][15282] Authorization failure occurred.
2018-01-05 18:31:51,621 [salt.transport.zeromq][ERROR   ][15282] Some exception handling a payload from minion
Traceback (most recent call last):
  File "/usr/lib/python2.7/dist-packages/salt/transport/zeromq.py", line 620, in handle_message
    ret, req_opts = yield self.payload_handler(payload)
  File "/usr/lib/python2.7/dist-packages/tornado/gen.py", line 870, in run
    value = future.result()
  File "/usr/lib/python2.7/dist-packages/tornado/concurrent.py", line 215, in result
    raise_exc_info(self._exc_info)
  File "/usr/lib/python2.7/dist-packages/tornado/gen.py", line 215, in wrapper
    result = func(*args, **kwargs)
  File "/usr/lib/python2.7/dist-packages/salt/master.py", line 894, in _handle_payload
    'clear': self._handle_clear}[key](load)
  File "/usr/lib/python2.7/dist-packages/salt/master.py", line 908, in _handle_clear
    return getattr(self.clear_funcs, load['cmd'])(load), {'fun': 'send_clear'}
  File "/usr/lib/python2.7/dist-packages/salt/master.py", line 1710, in runner
    if not self.ckminions.runner_check(auth_list, clear_load['fun']):
  File "/usr/lib/python2.7/dist-packages/salt/utils/minions.py", line 1028, in runner_check
    for ind in auth_list:
TypeError: 'NoneType' object is not iterable
2018-01-05 18:31:51,645 [salt.auth        ][WARNING ][15280] Authorization failure occurred.
2018-01-05 18:31:51,646 [salt.transport.zeromq][ERROR   ][15280] Some exception handling a payload from minion
Traceback (most recent call last):
  File "/usr/lib/python2.7/dist-packages/salt/transport/zeromq.py", line 620, in handle_message
    ret, req_opts = yield self.payload_handler(payload)
  File "/usr/lib/python2.7/dist-packages/tornado/gen.py", line 870, in run
    value = future.result()
  File "/usr/lib/python2.7/dist-packages/tornado/concurrent.py", line 215, in result
    raise_exc_info(self._exc_info)
  File "/usr/lib/python2.7/dist-packages/tornado/gen.py", line 215, in wrapper
    result = func(*args, **kwargs)
  File "/usr/lib/python2.7/dist-packages/salt/master.py", line 894, in _handle_payload
    'clear': self._handle_clear}[key](load)
  File "/usr/lib/python2.7/dist-packages/salt/master.py", line 908, in _handle_clear
    return getattr(self.clear_funcs, load['cmd'])(load), {'fun': 'send_clear'}
  File "/usr/lib/python2.7/dist-packages/salt/master.py", line 1710, in runner
    if not self.ckminions.runner_check(auth_list, clear_load['fun']):
  File "/usr/lib/python2.7/dist-packages/salt/utils/minions.py", line 1028, in runner_check
    for ind in auth_list:
TypeError: 'NoneType' object is not iterable
2018-01-05 18:31:51,677 [salt.auth        ][WARNING ][15288] Authorization failure occurred.
2018-01-05 18:31:51,677 [salt.transport.zeromq][ERROR   ][15288] Some exception handling a payload from minion
Traceback (most recent call last):
  File "/usr/lib/python2.7/dist-packages/salt/transport/zeromq.py", line 620, in handle_message
    ret, req_opts = yield self.payload_handler(payload)
  File "/usr/lib/python2.7/dist-packages/tornado/gen.py", line 870, in run
    value = future.result()
  File "/usr/lib/python2.7/dist-packages/tornado/concurrent.py", line 215, in result
    raise_exc_info(self._exc_info)
  File "/usr/lib/python2.7/dist-packages/tornado/gen.py", line 215, in wrapper
    result = func(*args, **kwargs)
  File "/usr/lib/python2.7/dist-packages/salt/master.py", line 894, in _handle_payload
    'clear': self._handle_clear}[key](load)
  File "/usr/lib/python2.7/dist-packages/salt/master.py", line 908, in _handle_clear
    return getattr(self.clear_funcs, load['cmd'])(load), {'fun': 'send_clear'}
  File "/usr/lib/python2.7/dist-packages/salt/master.py", line 1710, in runner
    if not self.ckminions.runner_check(auth_list, clear_load['fun']):
  File "/usr/lib/python2.7/dist-packages/salt/utils/minions.py", line 1028, in runner_check
    for ind in auth_list:
TypeError: 'NoneType' object is not iterable
2018-01-05 18:31:51,680 [salt.auth        ][WARNING ][15279] Authorization failure occurred.
2018-01-05 18:31:51,681 [salt.transport.zeromq][ERROR   ][15279] Some exception handling a payload from minion
Traceback (most recent call last):
  File "/usr/lib/python2.7/dist-packages/salt/transport/zeromq.py", line 620, in handle_message
    ret, req_opts = yield self.payload_handler(payload)
  File "/usr/lib/python2.7/dist-packages/tornado/gen.py", line 870, in run
    value = future.result()
  File "/usr/lib/python2.7/dist-packages/tornado/concurrent.py", line 215, in result
    raise_exc_info(self._exc_info)
  File "/usr/lib/python2.7/dist-packages/tornado/gen.py", line 215, in wrapper
    result = func(*args, **kwargs)
  File "/usr/lib/python2.7/dist-packages/salt/master.py", line 894, in _handle_payload
    'clear': self._handle_clear}[key](load)
  File "/usr/lib/python2.7/dist-packages/salt/master.py", line 908, in _handle_clear
    return getattr(self.clear_funcs, load['cmd'])(load), {'fun': 'send_clear'}
  File "/usr/lib/python2.7/dist-packages/salt/master.py", line 1710, in runner
    if not self.ckminions.runner_check(auth_list, clear_load['fun']):
  File "/usr/lib/python2.7/dist-packages/salt/utils/minions.py", line 1028, in runner_check
    for ind in auth_list:
TypeError: 'NoneType' object is not iterable
2018-01-05 18:31:51,730 [salt.auth        ][WARNING ][15281] Authorization failure occurred.
2018-01-05 18:31:51,730 [salt.master      ][WARNING ][15281] Authentication failure of type "token" occurred.
2018-01-05 18:31:57,379 [salt.auth        ][WARNING ][15280] Authorization failure occurred.
2018-01-05 18:31:57,380 [salt.transport.zeromq][ERROR   ][15280] Some exception handling a payload from minion
Traceback (most recent call last):
  File "/usr/lib/python2.7/dist-packages/salt/transport/zeromq.py", line 620, in handle_message
    ret, req_opts = yield self.payload_handler(payload)
  File "/usr/lib/python2.7/dist-packages/tornado/gen.py", line 870, in run
    value = future.result()
  File "/usr/lib/python2.7/dist-packages/tornado/concurrent.py", line 215, in result
    raise_exc_info(self._exc_info)
  File "/usr/lib/python2.7/dist-packages/tornado/gen.py", line 215, in wrapper
    result = func(*args, **kwargs)
  File "/usr/lib/python2.7/dist-packages/salt/master.py", line 894, in _handle_payload
    'clear': self._handle_clear}[key](load)
  File "/usr/lib/python2.7/dist-packages/salt/master.py", line 908, in _handle_clear
    return getattr(self.clear_funcs, load['cmd'])(load), {'fun': 'send_clear'}
  File "/usr/lib/python2.7/dist-packages/salt/master.py", line 1710, in runner
    if not self.ckminions.runner_check(auth_list, clear_load['fun']):
  File "/usr/lib/python2.7/dist-packages/salt/utils/minions.py", line 1028, in runner_check
    for ind in auth_list:
TypeError: 'NoneType' object is not iterable
2018-01-05 18:32:37,200 [salt.auth        ][WARNING ][15288] Authorization failure occurred.
2018-01-05 18:32:37,200 [salt.master      ][WARNING ][15288] Authentication failure of type "token" occurred.
2018-01-05 18:32:44,717 [salt.auth        ][WARNING ][15281] Authorization failure occurred.
2018-01-05 18:32:44,717 [salt.master      ][WARNING ][15281] Authentication failure of type "token" occurred.
2018-01-05 18:32:58,877 [salt.auth        ][WARNING ][15280] Authorization failure occurred.
2018-01-05 18:32:58,877 [salt.transport.zeromq][ERROR   ][15280] Some exception handling a payload from minion
Traceback (most recent call last):
  File "/usr/lib/python2.7/dist-packages/salt/transport/zeromq.py", line 620, in handle_message
    ret, req_opts = yield self.payload_handler(payload)
  File "/usr/lib/python2.7/dist-packages/tornado/gen.py", line 870, in run
    value = future.result()
  File "/usr/lib/python2.7/dist-packages/tornado/concurrent.py", line 215, in result
    raise_exc_info(self._exc_info)
  File "/usr/lib/python2.7/dist-packages/tornado/gen.py", line 215, in wrapper
    result = func(*args, **kwargs)
  File "/usr/lib/python2.7/dist-packages/salt/master.py", line 894, in _handle_payload
    'clear': self._handle_clear}[key](load)
  File "/usr/lib/python2.7/dist-packages/salt/master.py", line 908, in _handle_clear
    return getattr(self.clear_funcs, load['cmd'])(load), {'fun': 'send_clear'}
  File "/usr/lib/python2.7/dist-packages/salt/master.py", line 1710, in runner
    if not self.ckminions.runner_check(auth_list, clear_load['fun']):
  File "/usr/lib/python2.7/dist-packages/salt/utils/minions.py", line 1028, in runner_check
    for ind in auth_list:
TypeError: 'NoneType' object is not iterable
2018-01-05 18:35:51,850 [salt.auth        ][WARNING ][15288] Authorization failure occurred.
2018-01-05 18:35:51,852 [salt.transport.zeromq][ERROR   ][15288] Some exception handling a payload from minion
Traceback (most recent call last):
  File "/usr/lib/python2.7/dist-packages/salt/transport/zeromq.py", line 620, in handle_message
    ret, req_opts = yield self.payload_handler(payload)
  File "/usr/lib/python2.7/dist-packages/tornado/gen.py", line 870, in run
    value = future.result()
  File "/usr/lib/python2.7/dist-packages/tornado/concurrent.py", line 215, in result
    raise_exc_info(self._exc_info)
  File "/usr/lib/python2.7/dist-packages/tornado/gen.py", line 215, in wrapper
    result = func(*args, **kwargs)
  File "/usr/lib/python2.7/dist-packages/salt/master.py", line 894, in _handle_payload
    'clear': self._handle_clear}[key](load)
  File "/usr/lib/python2.7/dist-packages/salt/master.py", line 908, in _handle_clear
    return getattr(self.clear_funcs, load['cmd'])(load), {'fun': 'send_clear'}
  File "/usr/lib/python2.7/dist-packages/salt/master.py", line 1710, in runner
    if not self.ckminions.runner_check(auth_list, clear_load['fun']):
  File "/usr/lib/python2.7/dist-packages/salt/utils/minions.py", line 1028, in runner_check
    for ind in auth_list:
TypeError: 'NoneType' object is not iterable
2018-01-05 18:35:51,853 [salt.auth        ][WARNING ][15279] Authorization failure occurred.
2018-01-05 18:35:51,853 [salt.transport.zeromq][ERROR   ][15279] Some exception handling a payload from minion
Traceback (most recent call last):
  File "/usr/lib/python2.7/dist-packages/salt/transport/zeromq.py", line 620, in handle_message
    ret, req_opts = yield self.payload_handler(payload)
  File "/usr/lib/python2.7/dist-packages/tornado/gen.py", line 870, in run
    value = future.result()
  File "/usr/lib/python2.7/dist-packages/tornado/concurrent.py", line 215, in result
    raise_exc_info(self._exc_info)
  File "/usr/lib/python2.7/dist-packages/tornado/gen.py", line 215, in wrapper
    result = func(*args, **kwargs)
  File "/usr/lib/python2.7/dist-packages/salt/master.py", line 894, in _handle_payload
    'clear': self._handle_clear}[key](load)
  File "/usr/lib/python2.7/dist-packages/salt/master.py", line 908, in _handle_clear
    return getattr(self.clear_funcs, load['cmd'])(load), {'fun': 'send_clear'}
  File "/usr/lib/python2.7/dist-packages/salt/master.py", line 1710, in runner
    if not self.ckminions.runner_check(auth_list, clear_load['fun']):
  File "/usr/lib/python2.7/dist-packages/salt/utils/minions.py", line 1028, in runner_check
    for ind in auth_list:
TypeError: 'NoneType' object is not iterable
2018-01-05 18:35:51,916 [salt.auth        ][WARNING ][15281] Authorization failure occurred.
2018-01-05 18:35:51,917 [salt.master      ][WARNING ][15281] Authentication failure of type "token" occurred.
2018-01-05 18:35:51,939 [salt.auth        ][WARNING ][15282] Authorization failure occurred.
2018-01-05 18:35:51,940 [salt.transport.zeromq][ERROR   ][15282] Some exception handling a payload from minion
Traceback (most recent call last):
  File "/usr/lib/python2.7/dist-packages/salt/transport/zeromq.py", line 620, in handle_message
    ret, req_opts = yield self.payload_handler(payload)
  File "/usr/lib/python2.7/dist-packages/tornado/gen.py", line 870, in run
    value = future.result()
  File "/usr/lib/python2.7/dist-packages/tornado/concurrent.py", line 215, in result
    raise_exc_info(self._exc_info)
  File "/usr/lib/python2.7/dist-packages/tornado/gen.py", line 215, in wrapper
    result = func(*args, **kwargs)
  File "/usr/lib/python2.7/dist-packages/salt/master.py", line 894, in _handle_payload
    'clear': self._handle_clear}[key](load)
  File "/usr/lib/python2.7/dist-packages/salt/master.py", line 908, in _handle_clear
    return getattr(self.clear_funcs, load['cmd'])(load), {'fun': 'send_clear'}
  File "/usr/lib/python2.7/dist-packages/salt/master.py", line 1710, in runner
    if not self.ckminions.runner_check(auth_list, clear_load['fun']):
  File "/usr/lib/python2.7/dist-packages/salt/utils/minions.py", line 1028, in runner_check
    for ind in auth_list:
TypeError: 'NoneType' object is not iterable
2018-01-05 18:35:57,588 [salt.auth        ][WARNING ][15280] Authorization failure occurred.
2018-01-05 18:35:57,588 [salt.transport.zeromq][ERROR   ][15280] Some exception handling a payload from minion
Traceback (most recent call last):
  File "/usr/lib/python2.7/dist-packages/salt/transport/zeromq.py", line 620, in handle_message
    ret, req_opts = yield self.payload_handler(payload)
  File "/usr/lib/python2.7/dist-packages/tornado/gen.py", line 870, in run
    value = future.result()
  File "/usr/lib/python2.7/dist-packages/tornado/concurrent.py", line 215, in result
    raise_exc_info(self._exc_info)
  File "/usr/lib/python2.7/dist-packages/tornado/gen.py", line 215, in wrapper
    result = func(*args, **kwargs)
  File "/usr/lib/python2.7/dist-packages/salt/master.py", line 894, in _handle_payload
    'clear': self._handle_clear}[key](load)
  File "/usr/lib/python2.7/dist-packages/salt/master.py", line 908, in _handle_clear
    return getattr(self.clear_funcs, load['cmd'])(load), {'fun': 'send_clear'}
  File "/usr/lib/python2.7/dist-packages/salt/master.py", line 1710, in runner
    if not self.ckminions.runner_check(auth_list, clear_load['fun']):
  File "/usr/lib/python2.7/dist-packages/salt/utils/minions.py", line 1028, in runner_check
    for ind in auth_list:
TypeError: 'NoneType' object is not iterable
2018-01-05 18:36:59,036 [salt.auth        ][WARNING ][15288] Authorization failure occurred.
2018-01-05 18:36:59,036 [salt.transport.zeromq][ERROR   ][15288] Some exception handling a payload from minion
Traceback (most recent call last):
  File "/usr/lib/python2.7/dist-packages/salt/transport/zeromq.py", line 620, in handle_message
    ret, req_opts = yield self.payload_handler(payload)
  File "/usr/lib/python2.7/dist-packages/tornado/gen.py", line 870, in run
    value = future.result()
  File "/usr/lib/python2.7/dist-packages/tornado/concurrent.py", line 215, in result
    raise_exc_info(self._exc_info)
  File "/usr/lib/python2.7/dist-packages/tornado/gen.py", line 215, in wrapper
    result = func(*args, **kwargs)
  File "/usr/lib/python2.7/dist-packages/salt/master.py", line 894, in _handle_payload
    'clear': self._handle_clear}[key](load)
  File "/usr/lib/python2.7/dist-packages/salt/master.py", line 908, in _handle_clear
    return getattr(self.clear_funcs, load['cmd'])(load), {'fun': 'send_clear'}
  File "/usr/lib/python2.7/dist-packages/salt/master.py", line 1710, in runner
    if not self.ckminions.runner_check(auth_list, clear_load['fun']):
  File "/usr/lib/python2.7/dist-packages/salt/utils/minions.py", line 1028, in runner_check
    for ind in auth_list:
TypeError: 'NoneType' object is not iterable
2018-01-05 18:38:05,717 [salt.auth        ][WARNING ][15282] Authorization failure occurred.
2018-01-05 18:38:05,717 [salt.transport.zeromq][ERROR   ][15282] Some exception handling a payload from minion
Traceback (most recent call last):
  File "/usr/lib/python2.7/dist-packages/salt/transport/zeromq.py", line 620, in handle_message
    ret, req_opts = yield self.payload_handler(payload)
  File "/usr/lib/python2.7/dist-packages/tornado/gen.py", line 870, in run
    value = future.result()
  File "/usr/lib/python2.7/dist-packages/tornado/concurrent.py", line 215, in result
    raise_exc_info(self._exc_info)
  File "/usr/lib/python2.7/dist-packages/tornado/gen.py", line 215, in wrapper
    result = func(*args, **kwargs)
  File "/usr/lib/python2.7/dist-packages/salt/master.py", line 894, in _handle_payload
    'clear': self._handle_clear}[key](load)
  File "/usr/lib/python2.7/dist-packages/salt/master.py", line 908, in _handle_clear
    return getattr(self.clear_funcs, load['cmd'])(load), {'fun': 'send_clear'}
  File "/usr/lib/python2.7/dist-packages/salt/master.py", line 1710, in runner
    if not self.ckminions.runner_check(auth_list, clear_load['fun']):
  File "/usr/lib/python2.7/dist-packages/salt/utils/minions.py", line 1028, in runner_check
    for ind in auth_list:
TypeError: 'NoneType' object is not iterable
2018-01-05 18:38:05,722 [salt.auth        ][WARNING ][15280] Authorization failure occurred.
2018-01-05 18:38:05,722 [salt.transport.zeromq][ERROR   ][15280] Some exception handling a payload from minion
Traceback (most recent call last):
  File "/usr/lib/python2.7/dist-packages/salt/transport/zeromq.py", line 620, in handle_message
    ret, req_opts = yield self.payload_handler(payload)
  File "/usr/lib/python2.7/dist-packages/tornado/gen.py", line 870, in run
    value = future.result()
  File "/usr/lib/python2.7/dist-packages/tornado/concurrent.py", line 215, in result
    raise_exc_info(self._exc_info)
  File "/usr/lib/python2.7/dist-packages/tornado/gen.py", line 215, in wrapper
    result = func(*args, **kwargs)
  File "/usr/lib/python2.7/dist-packages/salt/master.py", line 894, in _handle_payload
    'clear': self._handle_clear}[key](load)
  File "/usr/lib/python2.7/dist-packages/salt/master.py", line 908, in _handle_clear
    return getattr(self.clear_funcs, load['cmd'])(load), {'fun': 'send_clear'}
  File "/usr/lib/python2.7/dist-packages/salt/master.py", line 1710, in runner
    if not self.ckminions.runner_check(auth_list, clear_load['fun']):
  File "/usr/lib/python2.7/dist-packages/salt/utils/minions.py", line 1028, in runner_check
    for ind in auth_list:
TypeError: 'NoneType' object is not iterable
2018-01-05 18:38:05,774 [salt.auth        ][WARNING ][15288] Authorization failure occurred.
2018-01-05 18:38:05,775 [salt.transport.zeromq][ERROR   ][15288] Some exception handling a payload from minion
Traceback (most recent call last):
  File "/usr/lib/python2.7/dist-packages/salt/transport/zeromq.py", line 620, in handle_message
    ret, req_opts = yield self.payload_handler(payload)
  File "/usr/lib/python2.7/dist-packages/tornado/gen.py", line 870, in run
    value = future.result()
  File "/usr/lib/python2.7/dist-packages/tornado/concurrent.py", line 215, in result
    raise_exc_info(self._exc_info)
  File "/usr/lib/python2.7/dist-packages/tornado/gen.py", line 215, in wrapper
    result = func(*args, **kwargs)
  File "/usr/lib/python2.7/dist-packages/salt/master.py", line 894, in _handle_payload
    'clear': self._handle_clear}[key](load)
  File "/usr/lib/python2.7/dist-packages/salt/master.py", line 908, in _handle_clear
    return getattr(self.clear_funcs, load['cmd'])(load), {'fun': 'send_clear'}
  File "/usr/lib/python2.7/dist-packages/salt/master.py", line 1710, in runner
    if not self.ckminions.runner_check(auth_list, clear_load['fun']):
  File "/usr/lib/python2.7/dist-packages/salt/utils/minions.py", line 1028, in runner_check
    for ind in auth_list:
TypeError: 'NoneType' object is not iterable
2018-01-05 18:38:05,812 [salt.auth        ][WARNING ][15279] Authorization failure occurred.
2018-01-05 18:38:05,812 [salt.master      ][WARNING ][15279] Authentication failure of type "token" occurred.
2018-01-05 18:38:05,813 [salt.auth        ][WARNING ][15281] Authorization failure occurred.
2018-01-05 18:38:05,814 [salt.transport.zeromq][ERROR   ][15281] Some exception handling a payload from minion
Traceback (most recent call last):
  File "/usr/lib/python2.7/dist-packages/salt/transport/zeromq.py", line 620, in handle_message
    ret, req_opts = yield self.payload_handler(payload)
  File "/usr/lib/python2.7/dist-packages/tornado/gen.py", line 870, in run
    value = future.result()
  File "/usr/lib/python2.7/dist-packages/tornado/concurrent.py", line 215, in result
    raise_exc_info(self._exc_info)
  File "/usr/lib/python2.7/dist-packages/tornado/gen.py", line 215, in wrapper
    result = func(*args, **kwargs)
  File "/usr/lib/python2.7/dist-packages/salt/master.py", line 894, in _handle_payload
    'clear': self._handle_clear}[key](load)
  File "/usr/lib/python2.7/dist-packages/salt/master.py", line 908, in _handle_clear
    return getattr(self.clear_funcs, load['cmd'])(load), {'fun': 'send_clear'}
  File "/usr/lib/python2.7/dist-packages/salt/master.py", line 1710, in runner
    if not self.ckminions.runner_check(auth_list, clear_load['fun']):
  File "/usr/lib/python2.7/dist-packages/salt/utils/minions.py", line 1028, in runner_check
    for ind in auth_list:
TypeError: 'NoneType' object is not iterable
2018-01-05 18:38:11,019 [salt.auth        ][WARNING ][15280] Authorization failure occurred.
2018-01-05 18:38:11,019 [salt.auth        ][WARNING ][15288] Authorization failure occurred.
2018-01-05 18:38:11,019 [salt.transport.zeromq][ERROR   ][15280] Some exception handling a payload from minion
Traceback (most recent call last):
  File "/usr/lib/python2.7/dist-packages/salt/transport/zeromq.py", line 620, in handle_message
    ret, req_opts = yield self.payload_handler(payload)
  File "/usr/lib/python2.7/dist-packages/tornado/gen.py", line 870, in run
    value = future.result()
  File "/usr/lib/python2.7/dist-packages/tornado/concurrent.py", line 215, in result
    raise_exc_info(self._exc_info)
  File "/usr/lib/python2.7/dist-packages/tornado/gen.py", line 215, in wrapper
    result = func(*args, **kwargs)
  File "/usr/lib/python2.7/dist-packages/salt/master.py", line 894, in _handle_payload
    'clear': self._handle_clear}[key](load)
  File "/usr/lib/python2.7/dist-packages/salt/master.py", line 908, in _handle_clear
    return getattr(self.clear_funcs, load['cmd'])(load), {'fun': 'send_clear'}
  File "/usr/lib/python2.7/dist-packages/salt/master.py", line 1710, in runner
    if not self.ckminions.runner_check(auth_list, clear_load['fun']):
  File "/usr/lib/python2.7/dist-packages/salt/utils/minions.py", line 1028, in runner_check
    for ind in auth_list:
TypeError: 'NoneType' object is not iterable
2018-01-05 18:38:11,020 [salt.transport.zeromq][ERROR   ][15288] Some exception handling a payload from minion
Traceback (most recent call last):
  File "/usr/lib/python2.7/dist-packages/salt/transport/zeromq.py", line 620, in handle_message
    ret, req_opts = yield self.payload_handler(payload)
  File "/usr/lib/python2.7/dist-packages/tornado/gen.py", line 870, in run
    value = future.result()
  File "/usr/lib/python2.7/dist-packages/tornado/concurrent.py", line 215, in result
    raise_exc_info(self._exc_info)
  File "/usr/lib/python2.7/dist-packages/tornado/gen.py", line 215, in wrapper
    result = func(*args, **kwargs)
  File "/usr/lib/python2.7/dist-packages/salt/master.py", line 894, in _handle_payload
    'clear': self._handle_clear}[key](load)
  File "/usr/lib/python2.7/dist-packages/salt/master.py", line 908, in _handle_clear
    return getattr(self.clear_funcs, load['cmd'])(load), {'fun': 'send_clear'}
  File "/usr/lib/python2.7/dist-packages/salt/master.py", line 1710, in runner
    if not self.ckminions.runner_check(auth_list, clear_load['fun']):
  File "/usr/lib/python2.7/dist-packages/salt/utils/minions.py", line 1028, in runner_check
    for ind in auth_list:
TypeError: 'NoneType' object is not iterable
2018-01-05 18:40:01,990 [salt.auth        ][WARNING ][15279] Authorization failure occurred.
2018-01-05 18:40:01,991 [salt.transport.zeromq][ERROR   ][15279] Some exception handling a payload from minion
Traceback (most recent call last):
  File "/usr/lib/python2.7/dist-packages/salt/transport/zeromq.py", line 620, in handle_message
    ret, req_opts = yield self.payload_handler(payload)
  File "/usr/lib/python2.7/dist-packages/tornado/gen.py", line 870, in run
    value = future.result()
  File "/usr/lib/python2.7/dist-packages/tornado/concurrent.py", line 215, in result
    raise_exc_info(self._exc_info)
  File "/usr/lib/python2.7/dist-packages/tornado/gen.py", line 215, in wrapper
    result = func(*args, **kwargs)
  File "/usr/lib/python2.7/dist-packages/salt/master.py", line 894, in _handle_payload
    'clear': self._handle_clear}[key](load)
  File "/usr/lib/python2.7/dist-packages/salt/master.py", line 908, in _handle_clear
    return getattr(self.clear_funcs, load['cmd'])(load), {'fun': 'send_clear'}
  File "/usr/lib/python2.7/dist-packages/salt/master.py", line 1710, in runner
    if not self.ckminions.runner_check(auth_list, clear_load['fun']):
  File "/usr/lib/python2.7/dist-packages/salt/utils/minions.py", line 1028, in runner_check
    for ind in auth_list:
TypeError: 'NoneType' object is not iterable
2018-01-05 18:40:01,993 [salt.auth        ][WARNING ][15281] Authorization failure occurred.
2018-01-05 18:40:01,994 [salt.transport.zeromq][ERROR   ][15281] Some exception handling a payload from minion
Traceback (most recent call last):
  File "/usr/lib/python2.7/dist-packages/salt/transport/zeromq.py", line 620, in handle_message
    ret, req_opts = yield self.payload_handler(payload)
  File "/usr/lib/python2.7/dist-packages/tornado/gen.py", line 870, in run
    value = future.result()
  File "/usr/lib/python2.7/dist-packages/tornado/concurrent.py", line 215, in result
    raise_exc_info(self._exc_info)
  File "/usr/lib/python2.7/dist-packages/tornado/gen.py", line 215, in wrapper
    result = func(*args, **kwargs)
  File "/usr/lib/python2.7/dist-packages/salt/master.py", line 894, in _handle_payload
    'clear': self._handle_clear}[key](load)
  File "/usr/lib/python2.7/dist-packages/salt/master.py", line 908, in _handle_clear
    return getattr(self.clear_funcs, load['cmd'])(load), {'fun': 'send_clear'}
  File "/usr/lib/python2.7/dist-packages/salt/master.py", line 1710, in runner
    if not self.ckminions.runner_check(auth_list, clear_load['fun']):
  File "/usr/lib/python2.7/dist-packages/salt/utils/minions.py", line 1028, in runner_check
    for ind in auth_list:
TypeError: 'NoneType' object is not iterable
2018-01-05 18:40:02,252 [salt.auth        ][WARNING ][15282] Authorization failure occurred.
2018-01-05 18:40:02,253 [salt.transport.zeromq][ERROR   ][15282] Some exception handling a payload from minion
Traceback (most recent call last):
  File "/usr/lib/python2.7/dist-packages/salt/transport/zeromq.py", line 620, in handle_message
    ret, req_opts = yield self.payload_handler(payload)
  File "/usr/lib/python2.7/dist-packages/tornado/gen.py", line 870, in run
    value = future.result()
  File "/usr/lib/python2.7/dist-packages/tornado/concurrent.py", line 215, in result
    raise_exc_info(self._exc_info)
  File "/usr/lib/python2.7/dist-packages/tornado/gen.py", line 215, in wrapper
    result = func(*args, **kwargs)
  File "/usr/lib/python2.7/dist-packages/salt/master.py", line 894, in _handle_payload
    'clear': self._handle_clear}[key](load)
  File "/usr/lib/python2.7/dist-packages/salt/master.py", line 908, in _handle_clear
    return getattr(self.clear_funcs, load['cmd'])(load), {'fun': 'send_clear'}
  File "/usr/lib/python2.7/dist-packages/salt/master.py", line 1710, in runner
    if not self.ckminions.runner_check(auth_list, clear_load['fun']):
  File "/usr/lib/python2.7/dist-packages/salt/utils/minions.py", line 1028, in runner_check
    for ind in auth_list:
TypeError: 'NoneType' object is not iterable
2018-01-05 18:40:12,621 [salt.auth        ][WARNING ][15279] Authorization failure occurred.
2018-01-05 18:40:12,622 [salt.transport.zeromq][ERROR   ][15279] Some exception handling a payload from minion
Traceback (most recent call last):
  File "/usr/lib/python2.7/dist-packages/salt/transport/zeromq.py", line 620, in handle_message
    ret, req_opts = yield self.payload_handler(payload)
  File "/usr/lib/python2.7/dist-packages/tornado/gen.py", line 870, in run
    value = future.result()
  File "/usr/lib/python2.7/dist-packages/tornado/concurrent.py", line 215, in result
    raise_exc_info(self._exc_info)
  File "/usr/lib/python2.7/dist-packages/tornado/gen.py", line 215, in wrapper
    result = func(*args, **kwargs)
  File "/usr/lib/python2.7/dist-packages/salt/master.py", line 894, in _handle_payload
    'clear': self._handle_clear}[key](load)
  File "/usr/lib/python2.7/dist-packages/salt/master.py", line 908, in _handle_clear
    return getattr(self.clear_funcs, load['cmd'])(load), {'fun': 'send_clear'}
  File "/usr/lib/python2.7/dist-packages/salt/master.py", line 1710, in runner
    if not self.ckminions.runner_check(auth_list, clear_load['fun']):
  File "/usr/lib/python2.7/dist-packages/salt/utils/minions.py", line 1028, in runner_check
    for ind in auth_list:
TypeError: 'NoneType' object is not iterable
2018-01-05 18:40:12,663 [salt.auth        ][WARNING ][15281] Authorization failure occurred.
2018-01-05 18:40:12,663 [salt.transport.zeromq][ERROR   ][15281] Some exception handling a payload from minion
Traceback (most recent call last):
  File "/usr/lib/python2.7/dist-packages/salt/transport/zeromq.py", line 620, in handle_message
    ret, req_opts = yield self.payload_handler(payload)
  File "/usr/lib/python2.7/dist-packages/tornado/gen.py", line 870, in run
    value = future.result()
  File "/usr/lib/python2.7/dist-packages/tornado/concurrent.py", line 215, in result
    raise_exc_info(self._exc_info)
  File "/usr/lib/python2.7/dist-packages/tornado/gen.py", line 215, in wrapper
    result = func(*args, **kwargs)
  File "/usr/lib/python2.7/dist-packages/salt/master.py", line 894, in _handle_payload
    'clear': self._handle_clear}[key](load)
  File "/usr/lib/python2.7/dist-packages/salt/master.py", line 908, in _handle_clear
    return getattr(self.clear_funcs, load['cmd'])(load), {'fun': 'send_clear'}
  File "/usr/lib/python2.7/dist-packages/salt/master.py", line 1710, in runner
    if not self.ckminions.runner_check(auth_list, clear_load['fun']):
  File "/usr/lib/python2.7/dist-packages/salt/utils/minions.py", line 1028, in runner_check
    for ind in auth_list:
TypeError: 'NoneType' object is not iterable
2018-01-05 18:40:12,693 [salt.auth        ][WARNING ][15282] Authorization failure occurred.
2018-01-05 18:40:12,693 [salt.transport.zeromq][ERROR   ][15282] Some exception handling a payload from minion
Traceback (most recent call last):
  File "/usr/lib/python2.7/dist-packages/salt/transport/zeromq.py", line 620, in handle_message
    ret, req_opts = yield self.payload_handler(payload)
  File "/usr/lib/python2.7/dist-packages/tornado/gen.py", line 870, in run
    value = future.result()
  File "/usr/lib/python2.7/dist-packages/tornado/concurrent.py", line 215, in result
    raise_exc_info(self._exc_info)
  File "/usr/lib/python2.7/dist-packages/tornado/gen.py", line 215, in wrapper
    result = func(*args, **kwargs)
  File "/usr/lib/python2.7/dist-packages/salt/master.py", line 894, in _handle_payload
    'clear': self._handle_clear}[key](load)
  File "/usr/lib/python2.7/dist-packages/salt/master.py", line 908, in _handle_clear
    return getattr(self.clear_funcs, load['cmd'])(load), {'fun': 'send_clear'}
  File "/usr/lib/python2.7/dist-packages/salt/master.py", line 1710, in runner
    if not self.ckminions.runner_check(auth_list, clear_load['fun']):
  File "/usr/lib/python2.7/dist-packages/salt/utils/minions.py", line 1028, in runner_check
    for ind in auth_list:
TypeError: 'NoneType' object is not iterable
2018-01-05 18:40:12,727 [salt.auth        ][WARNING ][15280] Authorization failure occurred.
2018-01-05 18:40:12,727 [salt.master      ][WARNING ][15280] Authentication failure of type "token" occurred.
2018-01-05 18:40:12,743 [salt.auth        ][WARNING ][15288] Authorization failure occurred.
2018-01-05 18:40:12,743 [salt.transport.zeromq][ERROR   ][15288] Some exception handling a payload from minion
Traceback (most recent call last):
  File "/usr/lib/python2.7/dist-packages/salt/transport/zeromq.py", line 620, in handle_message
    ret, req_opts = yield self.payload_handler(payload)
  File "/usr/lib/python2.7/dist-packages/tornado/gen.py", line 870, in run
    value = future.result()
  File "/usr/lib/python2.7/dist-packages/tornado/concurrent.py", line 215, in result
    raise_exc_info(self._exc_info)
  File "/usr/lib/python2.7/dist-packages/tornado/gen.py", line 215, in wrapper
    result = func(*args, **kwargs)
  File "/usr/lib/python2.7/dist-packages/salt/master.py", line 894, in _handle_payload
    'clear': self._handle_clear}[key](load)
  File "/usr/lib/python2.7/dist-packages/salt/master.py", line 908, in _handle_clear
    return getattr(self.clear_funcs, load['cmd'])(load), {'fun': 'send_clear'}
  File "/usr/lib/python2.7/dist-packages/salt/master.py", line 1710, in runner
    if not self.ckminions.runner_check(auth_list, clear_load['fun']):
  File "/usr/lib/python2.7/dist-packages/salt/utils/minions.py", line 1028, in runner_check
    for ind in auth_list:
TypeError: 'NoneType' object is not iterable
2018-01-05 18:40:47,792 [salt.auth        ][WARNING ][15282] Authorization failure occurred.
2018-01-05 18:40:47,793 [salt.transport.zeromq][ERROR   ][15282] Some exception handling a payload from minion
Traceback (most recent call last):
  File "/usr/lib/python2.7/dist-packages/salt/transport/zeromq.py", line 620, in handle_message
    ret, req_opts = yield self.payload_handler(payload)
  File "/usr/lib/python2.7/dist-packages/tornado/gen.py", line 870, in run
    value = future.result()
  File "/usr/lib/python2.7/dist-packages/tornado/concurrent.py", line 215, in result
    raise_exc_info(self._exc_info)
  File "/usr/lib/python2.7/dist-packages/tornado/gen.py", line 215, in wrapper
    result = func(*args, **kwargs)
  File "/usr/lib/python2.7/dist-packages/salt/master.py", line 894, in _handle_payload
    'clear': self._handle_clear}[key](load)
  File "/usr/lib/python2.7/dist-packages/salt/master.py", line 908, in _handle_clear
    return getattr(self.clear_funcs, load['cmd'])(load), {'fun': 'send_clear'}
  File "/usr/lib/python2.7/dist-packages/salt/master.py", line 1710, in runner
    if not self.ckminions.runner_check(auth_list, clear_load['fun']):
  File "/usr/lib/python2.7/dist-packages/salt/utils/minions.py", line 1028, in runner_check
    for ind in auth_list:
TypeError: 'NoneType' object is not iterable
2018-01-05 18:40:47,822 [salt.auth        ][WARNING ][15280] Authorization failure occurred.
2018-01-05 18:40:47,822 [salt.transport.zeromq][ERROR   ][15280] Some exception handling a payload from minion
Traceback (most recent call last):
  File "/usr/lib/python2.7/dist-packages/salt/transport/zeromq.py", line 620, in handle_message
    ret, req_opts = yield self.payload_handler(payload)
  File "/usr/lib/python2.7/dist-packages/tornado/gen.py", line 870, in run
    value = future.result()
  File "/usr/lib/python2.7/dist-packages/tornado/concurrent.py", line 215, in result
    raise_exc_info(self._exc_info)
  File "/usr/lib/python2.7/dist-packages/tornado/gen.py", line 215, in wrapper
    result = func(*args, **kwargs)
  File "/usr/lib/python2.7/dist-packages/salt/master.py", line 894, in _handle_payload
    'clear': self._handle_clear}[key](load)
  File "/usr/lib/python2.7/dist-packages/salt/master.py", line 908, in _handle_clear
    return getattr(self.clear_funcs, load['cmd'])(load), {'fun': 'send_clear'}
  File "/usr/lib/python2.7/dist-packages/salt/master.py", line 1710, in runner
    if not self.ckminions.runner_check(auth_list, clear_load['fun']):
  File "/usr/lib/python2.7/dist-packages/salt/utils/minions.py", line 1028, in runner_check
    for ind in auth_list:
TypeError: 'NoneType' object is not iterable
2018-01-05 18:40:47,876 [salt.auth        ][WARNING ][15288] Authorization failure occurred.
2018-01-05 18:40:47,876 [salt.transport.zeromq][ERROR   ][15288] Some exception handling a payload from minion
Traceback (most recent call last):
  File "/usr/lib/python2.7/dist-packages/salt/transport/zeromq.py", line 620, in handle_message
    ret, req_opts = yield self.payload_handler(payload)
  File "/usr/lib/python2.7/dist-packages/tornado/gen.py", line 870, in run
    value = future.result()
  File "/usr/lib/python2.7/dist-packages/tornado/concurrent.py", line 215, in result
    raise_exc_info(self._exc_info)
  File "/usr/lib/python2.7/dist-packages/tornado/gen.py", line 215, in wrapper
    result = func(*args, **kwargs)
  File "/usr/lib/python2.7/dist-packages/salt/master.py", line 894, in _handle_payload
    'clear': self._handle_clear}[key](load)
  File "/usr/lib/python2.7/dist-packages/salt/master.py", line 908, in _handle_clear
    return getattr(self.clear_funcs, load['cmd'])(load), {'fun': 'send_clear'}
  File "/usr/lib/python2.7/dist-packages/salt/master.py", line 1710, in runner
    if not self.ckminions.runner_check(auth_list, clear_load['fun']):
  File "/usr/lib/python2.7/dist-packages/salt/utils/minions.py", line 1028, in runner_check
    for ind in auth_list:
TypeError: 'NoneType' object is not iterable
2018-01-05 18:40:47,880 [salt.auth        ][WARNING ][15279] Authorization failure occurred.
2018-01-05 18:40:47,880 [salt.transport.zeromq][ERROR   ][15279] Some exception handling a payload from minion
Traceback (most recent call last):
  File "/usr/lib/python2.7/dist-packages/salt/transport/zeromq.py", line 620, in handle_message
    ret, req_opts = yield self.payload_handler(payload)
  File "/usr/lib/python2.7/dist-packages/tornado/gen.py", line 870, in run
    value = future.result()
  File "/usr/lib/python2.7/dist-packages/tornado/concurrent.py", line 215, in result
    raise_exc_info(self._exc_info)
  File "/usr/lib/python2.7/dist-packages/tornado/gen.py", line 215, in wrapper
    result = func(*args, **kwargs)
  File "/usr/lib/python2.7/dist-packages/salt/master.py", line 894, in _handle_payload
    'clear': self._handle_clear}[key](load)
  File "/usr/lib/python2.7/dist-packages/salt/master.py", line 908, in _handle_clear
    return getattr(self.clear_funcs, load['cmd'])(load), {'fun': 'send_clear'}
  File "/usr/lib/python2.7/dist-packages/salt/master.py", line 1710, in runner
    if not self.ckminions.runner_check(auth_list, clear_load['fun']):
  File "/usr/lib/python2.7/dist-packages/salt/utils/minions.py", line 1028, in runner_check
    for ind in auth_list:
TypeError: 'NoneType' object is not iterable
2018-01-05 18:40:47,939 [salt.auth        ][WARNING ][15281] Authorization failure occurred.
2018-01-05 18:40:47,939 [salt.master      ][WARNING ][15281] Authentication failure of type "token" occurred.
2018-01-05 18:40:57,333 [salt.auth        ][WARNING ][15280] Authorization failure occurred.
2018-01-05 18:40:57,333 [salt.transport.zeromq][ERROR   ][15280] Some exception handling a payload from minion
Traceback (most recent call last):
  File "/usr/lib/python2.7/dist-packages/salt/transport/zeromq.py", line 620, in handle_message
    ret, req_opts = yield self.payload_handler(payload)
  File "/usr/lib/python2.7/dist-packages/tornado/gen.py", line 870, in run
    value = future.result()
  File "/usr/lib/python2.7/dist-packages/tornado/concurrent.py", line 215, in result
    raise_exc_info(self._exc_info)
  File "/usr/lib/python2.7/dist-packages/tornado/gen.py", line 215, in wrapper
    result = func(*args, **kwargs)
  File "/usr/lib/python2.7/dist-packages/salt/master.py", line 894, in _handle_payload
    'clear': self._handle_clear}[key](load)
  File "/usr/lib/python2.7/dist-packages/salt/master.py", line 908, in _handle_clear
    return getattr(self.clear_funcs, load['cmd'])(load), {'fun': 'send_clear'}
  File "/usr/lib/python2.7/dist-packages/salt/master.py", line 1710, in runner
    if not self.ckminions.runner_check(auth_list, clear_load['fun']):
  File "/usr/lib/python2.7/dist-packages/salt/utils/minions.py", line 1028, in runner_check
    for ind in auth_list:
TypeError: 'NoneType' object is not iterable
2018-01-05 18:40:57,372 [salt.auth        ][WARNING ][15288] Authorization failure occurred.
2018-01-05 18:40:57,373 [salt.transport.zeromq][ERROR   ][15288] Some exception handling a payload from minion
Traceback (most recent call last):
  File "/usr/lib/python2.7/dist-packages/salt/transport/zeromq.py", line 620, in handle_message
    ret, req_opts = yield self.payload_handler(payload)
  File "/usr/lib/python2.7/dist-packages/tornado/gen.py", line 870, in run
    value = future.result()
  File "/usr/lib/python2.7/dist-packages/tornado/concurrent.py", line 215, in result
    raise_exc_info(self._exc_info)
  File "/usr/lib/python2.7/dist-packages/tornado/gen.py", line 215, in wrapper
    result = func(*args, **kwargs)
  File "/usr/lib/python2.7/dist-packages/salt/master.py", line 894, in _handle_payload
    'clear': self._handle_clear}[key](load)
  File "/usr/lib/python2.7/dist-packages/salt/master.py", line 908, in _handle_clear
    return getattr(self.clear_funcs, load['cmd'])(load), {'fun': 'send_clear'}
  File "/usr/lib/python2.7/dist-packages/salt/master.py", line 1710, in runner
    if not self.ckminions.runner_check(auth_list, clear_load['fun']):
  File "/usr/lib/python2.7/dist-packages/salt/utils/minions.py", line 1028, in runner_check
    for ind in auth_list:
TypeError: 'NoneType' object is not iterable
2018-01-05 18:44:48,017 [salt.auth        ][WARNING ][15279] Authorization failure occurred.
2018-01-05 18:44:48,017 [salt.transport.zeromq][ERROR   ][15279] Some exception handling a payload from minion
Traceback (most recent call last):
  File "/usr/lib/python2.7/dist-packages/salt/transport/zeromq.py", line 620, in handle_message
    ret, req_opts = yield self.payload_handler(payload)
  File "/usr/lib/python2.7/dist-packages/tornado/gen.py", line 870, in run
    value = future.result()
  File "/usr/lib/python2.7/dist-packages/tornado/concurrent.py", line 215, in result
    raise_exc_info(self._exc_info)
  File "/usr/lib/python2.7/dist-packages/tornado/gen.py", line 215, in wrapper
    result = func(*args, **kwargs)
  File "/usr/lib/python2.7/dist-packages/salt/master.py", line 894, in _handle_payload
    'clear': self._handle_clear}[key](load)
  File "/usr/lib/python2.7/dist-packages/salt/master.py", line 908, in _handle_clear
    return getattr(self.clear_funcs, load['cmd'])(load), {'fun': 'send_clear'}
  File "/usr/lib/python2.7/dist-packages/salt/master.py", line 1710, in runner
    if not self.ckminions.runner_check(auth_list, clear_load['fun']):
  File "/usr/lib/python2.7/dist-packages/salt/utils/minions.py", line 1028, in runner_check
    for ind in auth_list:
TypeError: 'NoneType' object is not iterable
2018-01-05 18:44:48,076 [salt.auth        ][WARNING ][15281] Authorization failure occurred.
2018-01-05 18:44:48,077 [salt.transport.zeromq][ERROR   ][15281] Some exception handling a payload from minion
Traceback (most recent call last):
  File "/usr/lib/python2.7/dist-packages/salt/transport/zeromq.py", line 620, in handle_message
    ret, req_opts = yield self.payload_handler(payload)
  File "/usr/lib/python2.7/dist-packages/tornado/gen.py", line 870, in run
    value = future.result()
  File "/usr/lib/python2.7/dist-packages/tornado/concurrent.py", line 215, in result
    raise_exc_info(self._exc_info)
  File "/usr/lib/python2.7/dist-packages/tornado/gen.py", line 215, in wrapper
    result = func(*args, **kwargs)
  File "/usr/lib/python2.7/dist-packages/salt/master.py", line 894, in _handle_payload
    'clear': self._handle_clear}[key](load)
  File "/usr/lib/python2.7/dist-packages/salt/master.py", line 908, in _handle_clear
    return getattr(self.clear_funcs, load['cmd'])(load), {'fun': 'send_clear'}
  File "/usr/lib/python2.7/dist-packages/salt/master.py", line 1710, in runner
    if not self.ckminions.runner_check(auth_list, clear_load['fun']):
  File "/usr/lib/python2.7/dist-packages/salt/utils/minions.py", line 1028, in runner_check
    for ind in auth_list:
TypeError: 'NoneType' object is not iterable
2018-01-05 18:44:48,102 [salt.auth        ][WARNING ][15282] Authorization failure occurred.
2018-01-05 18:44:48,102 [salt.master      ][WARNING ][15282] Authentication failure of type "token" occurred.
2018-01-05 18:48:03,694 [salt.auth        ][WARNING ][15288] Authorization failure occurred.
2018-01-05 18:48:03,694 [salt.transport.zeromq][ERROR   ][15288] Some exception handling a payload from minion
Traceback (most recent call last):
  File "/usr/lib/python2.7/dist-packages/salt/transport/zeromq.py", line 620, in handle_message
    ret, req_opts = yield self.payload_handler(payload)
  File "/usr/lib/python2.7/dist-packages/tornado/gen.py", line 870, in run
    value = future.result()
  File "/usr/lib/python2.7/dist-packages/tornado/concurrent.py", line 215, in result
    raise_exc_info(self._exc_info)
  File "/usr/lib/python2.7/dist-packages/tornado/gen.py", line 215, in wrapper
    result = func(*args, **kwargs)
  File "/usr/lib/python2.7/dist-packages/salt/master.py", line 894, in _handle_payload
    'clear': self._handle_clear}[key](load)
  File "/usr/lib/python2.7/dist-packages/salt/master.py", line 908, in _handle_clear
    return getattr(self.clear_funcs, load['cmd'])(load), {'fun': 'send_clear'}
  File "/usr/lib/python2.7/dist-packages/salt/master.py", line 1710, in runner
    if not self.ckminions.runner_check(auth_list, clear_load['fun']):
  File "/usr/lib/python2.7/dist-packages/salt/utils/minions.py", line 1028, in runner_check
    for ind in auth_list:
TypeError: 'NoneType' object is not iterable
2018-01-05 18:48:03,739 [salt.auth        ][WARNING ][15279] Authorization failure occurred.
2018-01-05 18:48:03,740 [salt.auth        ][WARNING ][15281] Authorization failure occurred.
2018-01-05 18:48:03,740 [salt.transport.zeromq][ERROR   ][15281] Some exception handling a payload from minion
Traceback (most recent call last):
  File "/usr/lib/python2.7/dist-packages/salt/transport/zeromq.py", line 620, in handle_message
    ret, req_opts = yield self.payload_handler(payload)
  File "/usr/lib/python2.7/dist-packages/tornado/gen.py", line 870, in run
    value = future.result()
  File "/usr/lib/python2.7/dist-packages/tornado/concurrent.py", line 215, in result
    raise_exc_info(self._exc_info)
  File "/usr/lib/python2.7/dist-packages/tornado/gen.py", line 215, in wrapper
    result = func(*args, **kwargs)
  File "/usr/lib/python2.7/dist-packages/salt/master.py", line 894, in _handle_payload
    'clear': self._handle_clear}[key](load)
  File "/usr/lib/python2.7/dist-packages/salt/master.py", line 908, in _handle_clear
    return getattr(self.clear_funcs, load['cmd'])(load), {'fun': 'send_clear'}
  File "/usr/lib/python2.7/dist-packages/salt/master.py", line 1710, in runner
    if not self.ckminions.runner_check(auth_list, clear_load['fun']):
  File "/usr/lib/python2.7/dist-packages/salt/utils/minions.py", line 1028, in runner_check
    for ind in auth_list:
TypeError: 'NoneType' object is not iterable
2018-01-05 18:48:03,739 [salt.transport.zeromq][ERROR   ][15279] Some exception handling a payload from minion
Traceback (most recent call last):
  File "/usr/lib/python2.7/dist-packages/salt/transport/zeromq.py", line 620, in handle_message
    ret, req_opts = yield self.payload_handler(payload)
  File "/usr/lib/python2.7/dist-packages/tornado/gen.py", line 870, in run
    value = future.result()
  File "/usr/lib/python2.7/dist-packages/tornado/concurrent.py", line 215, in result
    raise_exc_info(self._exc_info)
  File "/usr/lib/python2.7/dist-packages/tornado/gen.py", line 215, in wrapper
    result = func(*args, **kwargs)
  File "/usr/lib/python2.7/dist-packages/salt/master.py", line 894, in _handle_payload
    'clear': self._handle_clear}[key](load)
  File "/usr/lib/python2.7/dist-packages/salt/master.py", line 908, in _handle_clear
    return getattr(self.clear_funcs, load['cmd'])(load), {'fun': 'send_clear'}
  File "/usr/lib/python2.7/dist-packages/salt/master.py", line 1710, in runner
    if not self.ckminions.runner_check(auth_list, clear_load['fun']):
  File "/usr/lib/python2.7/dist-packages/salt/utils/minions.py", line 1028, in runner_check
    for ind in auth_list:
TypeError: 'NoneType' object is not iterable
2018-01-05 18:48:03,790 [salt.auth        ][WARNING ][15282] Authorization failure occurred.
2018-01-05 18:48:03,790 [salt.master      ][WARNING ][15282] Authentication failure of type "token" occurred.
2018-01-05 18:48:03,807 [salt.auth        ][WARNING ][15280] Authorization failure occurred.
2018-01-05 18:48:03,808 [salt.transport.zeromq][ERROR   ][15280] Some exception handling a payload from minion
Traceback (most recent call last):
  File "/usr/lib/python2.7/dist-packages/salt/transport/zeromq.py", line 620, in handle_message
    ret, req_opts = yield self.payload_handler(payload)
  File "/usr/lib/python2.7/dist-packages/tornado/gen.py", line 870, in run
    value = future.result()
  File "/usr/lib/python2.7/dist-packages/tornado/concurrent.py", line 215, in result
    raise_exc_info(self._exc_info)
  File "/usr/lib/python2.7/dist-packages/tornado/gen.py", line 215, in wrapper
    result = func(*args, **kwargs)
  File "/usr/lib/python2.7/dist-packages/salt/master.py", line 894, in _handle_payload
    'clear': self._handle_clear}[key](load)
  File "/usr/lib/python2.7/dist-packages/salt/master.py", line 908, in _handle_clear
    return getattr(self.clear_funcs, load['cmd'])(load), {'fun': 'send_clear'}
  File "/usr/lib/python2.7/dist-packages/salt/master.py", line 1710, in runner
    if not self.ckminions.runner_check(auth_list, clear_load['fun']):
  File "/usr/lib/python2.7/dist-packages/salt/utils/minions.py", line 1028, in runner_check
    for ind in auth_list:
TypeError: 'NoneType' object is not iterable
